[2022-07-12 14:48:54,979] {taskinstance.py:1179} INFO - Dependencies all met for <TaskInstance: data_ingestion_local.ingest_data manual__2022-07-12T14:48:37.804921+00:00 [queued]>
[2022-07-12 14:48:54,998] {taskinstance.py:1179} INFO - Dependencies all met for <TaskInstance: data_ingestion_local.ingest_data manual__2022-07-12T14:48:37.804921+00:00 [queued]>
[2022-07-12 14:48:54,998] {taskinstance.py:1376} INFO - 
--------------------------------------------------------------------------------
[2022-07-12 14:48:54,998] {taskinstance.py:1377} INFO - Starting attempt 1 of 2
[2022-07-12 14:48:54,998] {taskinstance.py:1378} INFO - 
--------------------------------------------------------------------------------
[2022-07-12 14:48:55,028] {taskinstance.py:1397} INFO - Executing <Task(PythonOperator): ingest_data> on 2022-07-12 14:48:37.804921+00:00
[2022-07-12 14:48:55,034] {standard_task_runner.py:52} INFO - Started process 262 to run task
[2022-07-12 14:48:55,042] {standard_task_runner.py:79} INFO - Running: ['airflow', 'tasks', 'run', 'data_ingestion_local', 'ingest_data', 'manual__2022-07-12T14:48:37.804921+00:00', '--job-id', '7', '--raw', '--subdir', 'DAGS_FOLDER/data_ingestion_local_dag.py', '--cfg-path', '/tmp/tmpzaqfzo23', '--error-file', '/tmp/tmppeov3iu5']
[2022-07-12 14:48:55,044] {standard_task_runner.py:80} INFO - Job 7: Subtask ingest_data
[2022-07-12 14:48:55,161] {task_command.py:371} INFO - Running <TaskInstance: data_ingestion_local.ingest_data manual__2022-07-12T14:48:37.804921+00:00 [running]> on host 0ca5e21fb7fb
[2022-07-12 14:48:55,245] {logging_mixin.py:115} WARNING - /home/airflow/.local/lib/python3.7/site-packages/airflow/utils/context.py:202 AirflowContextDeprecationWarning: Accessing 'execution_date' from the template is deprecated and will be removed in a future version. Please use 'data_interval_start' or 'logical_date' instead.
[2022-07-12 14:48:55,327] {taskinstance.py:1591} INFO - Exporting the following env vars:
AIRFLOW_CTX_DAG_OWNER=airflow
AIRFLOW_CTX_DAG_ID=data_ingestion_local
AIRFLOW_CTX_TASK_ID=ingest_data
AIRFLOW_CTX_EXECUTION_DATE=2022-07-12T14:48:37.804921+00:00
AIRFLOW_CTX_TRY_NUMBER=1
AIRFLOW_CTX_DAG_RUN_ID=manual__2022-07-12T14:48:37.804921+00:00
[2022-07-12 14:48:57,225] {logging_mixin.py:115} INFO - yellow_taxi_2022_04.parquet /opt/airflow/output_2022-04.parquet
[2022-07-12 14:48:58,760] {taskinstance.py:1909} ERROR - Task failed with exception
Traceback (most recent call last):
  File "/home/airflow/.local/lib/python3.7/site-packages/sqlalchemy/engine/base.py", line 3243, in _wrap_pool_connect
    return fn()
  File "/home/airflow/.local/lib/python3.7/site-packages/sqlalchemy/pool/base.py", line 310, in connect
    return _ConnectionFairy._checkout(self)
  File "/home/airflow/.local/lib/python3.7/site-packages/sqlalchemy/pool/base.py", line 868, in _checkout
    fairy = _ConnectionRecord.checkout(pool)
  File "/home/airflow/.local/lib/python3.7/site-packages/sqlalchemy/pool/base.py", line 476, in checkout
    rec = pool._do_get()
  File "/home/airflow/.local/lib/python3.7/site-packages/sqlalchemy/pool/impl.py", line 146, in _do_get
    self._dec_overflow()
  File "/home/airflow/.local/lib/python3.7/site-packages/sqlalchemy/util/langhelpers.py", line 72, in __exit__
    with_traceback=exc_tb,
  File "/home/airflow/.local/lib/python3.7/site-packages/sqlalchemy/util/compat.py", line 207, in raise_
    raise exception
  File "/home/airflow/.local/lib/python3.7/site-packages/sqlalchemy/pool/impl.py", line 143, in _do_get
    return self._create_connection()
  File "/home/airflow/.local/lib/python3.7/site-packages/sqlalchemy/pool/base.py", line 256, in _create_connection
    return _ConnectionRecord(self)
  File "/home/airflow/.local/lib/python3.7/site-packages/sqlalchemy/pool/base.py", line 371, in __init__
    self.__connect()
  File "/home/airflow/.local/lib/python3.7/site-packages/sqlalchemy/pool/base.py", line 666, in __connect
    pool.logger.debug("Error on connect(): %s", e)
  File "/home/airflow/.local/lib/python3.7/site-packages/sqlalchemy/util/langhelpers.py", line 72, in __exit__
    with_traceback=exc_tb,
  File "/home/airflow/.local/lib/python3.7/site-packages/sqlalchemy/util/compat.py", line 207, in raise_
    raise exception
  File "/home/airflow/.local/lib/python3.7/site-packages/sqlalchemy/pool/base.py", line 661, in __connect
    self.dbapi_connection = connection = pool._invoke_creator(self)
  File "/home/airflow/.local/lib/python3.7/site-packages/sqlalchemy/engine/create.py", line 590, in connect
    return dialect.connect(*cargs, **cparams)
  File "/home/airflow/.local/lib/python3.7/site-packages/sqlalchemy/engine/default.py", line 584, in connect
    return self.dbapi.connect(*cargs, **cparams)
  File "/home/airflow/.local/lib/python3.7/site-packages/psycopg2/__init__.py", line 122, in connect
    conn = _connect(dsn, connection_factory=connection_factory, **kwasync)
psycopg2.OperationalError: connection to server at "pgdatabase" (172.20.0.2), port 5432 failed: FATAL:  password authentication failed for user "***"


The above exception was the direct cause of the following exception:

Traceback (most recent call last):
  File "/home/airflow/.local/lib/python3.7/site-packages/airflow/operators/python.py", line 171, in execute
    return_value = self.execute_callable()
  File "/home/airflow/.local/lib/python3.7/site-packages/airflow/operators/python.py", line 189, in execute_callable
    return self.python_callable(*self.op_args, **self.op_kwargs)
  File "/opt/airflow/dags/ingest_data.py", line 29, in ingest_callable
    df.to_sql(name=table_name, con=engine, if_exists='replace')
  File "/home/airflow/.local/lib/python3.7/site-packages/pandas/core/generic.py", line 2882, in to_sql
    method=method,
  File "/home/airflow/.local/lib/python3.7/site-packages/pandas/io/sql.py", line 728, in to_sql
    **engine_kwargs,
  File "/home/airflow/.local/lib/python3.7/site-packages/pandas/io/sql.py", line 1758, in to_sql
    dtype=dtype,
  File "/home/airflow/.local/lib/python3.7/site-packages/pandas/io/sql.py", line 1650, in prep_table
    table.create()
  File "/home/airflow/.local/lib/python3.7/site-packages/pandas/io/sql.py", line 856, in create
    if self.exists():
  File "/home/airflow/.local/lib/python3.7/site-packages/pandas/io/sql.py", line 840, in exists
    return self.pd_sql.has_table(self.name, self.schema)
  File "/home/airflow/.local/lib/python3.7/site-packages/pandas/io/sql.py", line 1783, in has_table
    insp = sa.inspect(self.connectable)
  File "/home/airflow/.local/lib/python3.7/site-packages/sqlalchemy/inspection.py", line 64, in inspect
    ret = reg(subject)
  File "/home/airflow/.local/lib/python3.7/site-packages/sqlalchemy/engine/reflection.py", line 182, in _engine_insp
    return Inspector._construct(Inspector._init_engine, bind)
  File "/home/airflow/.local/lib/python3.7/site-packages/sqlalchemy/engine/reflection.py", line 117, in _construct
    init(self, bind)
  File "/home/airflow/.local/lib/python3.7/site-packages/sqlalchemy/engine/reflection.py", line 128, in _init_engine
    engine.connect().close()
  File "/home/airflow/.local/lib/python3.7/site-packages/sqlalchemy/engine/base.py", line 3197, in connect
    return self._connection_cls(self, close_with_result=close_with_result)
  File "/home/airflow/.local/lib/python3.7/site-packages/sqlalchemy/engine/base.py", line 96, in __init__
    else engine.raw_connection()
  File "/home/airflow/.local/lib/python3.7/site-packages/sqlalchemy/engine/base.py", line 3276, in raw_connection
    return self._wrap_pool_connect(self.pool.connect, _connection)
  File "/home/airflow/.local/lib/python3.7/site-packages/sqlalchemy/engine/base.py", line 3247, in _wrap_pool_connect
    e, dialect, self
  File "/home/airflow/.local/lib/python3.7/site-packages/sqlalchemy/engine/base.py", line 2101, in _handle_dbapi_exception_noconnection
    sqlalchemy_exception, with_traceback=exc_info[2], from_=e
  File "/home/airflow/.local/lib/python3.7/site-packages/sqlalchemy/util/compat.py", line 207, in raise_
    raise exception
  File "/home/airflow/.local/lib/python3.7/site-packages/sqlalchemy/engine/base.py", line 3243, in _wrap_pool_connect
    return fn()
  File "/home/airflow/.local/lib/python3.7/site-packages/sqlalchemy/pool/base.py", line 310, in connect
    return _ConnectionFairy._checkout(self)
  File "/home/airflow/.local/lib/python3.7/site-packages/sqlalchemy/pool/base.py", line 868, in _checkout
    fairy = _ConnectionRecord.checkout(pool)
  File "/home/airflow/.local/lib/python3.7/site-packages/sqlalchemy/pool/base.py", line 476, in checkout
    rec = pool._do_get()
  File "/home/airflow/.local/lib/python3.7/site-packages/sqlalchemy/pool/impl.py", line 146, in _do_get
    self._dec_overflow()
  File "/home/airflow/.local/lib/python3.7/site-packages/sqlalchemy/util/langhelpers.py", line 72, in __exit__
    with_traceback=exc_tb,
  File "/home/airflow/.local/lib/python3.7/site-packages/sqlalchemy/util/compat.py", line 207, in raise_
    raise exception
  File "/home/airflow/.local/lib/python3.7/site-packages/sqlalchemy/pool/impl.py", line 143, in _do_get
    return self._create_connection()
  File "/home/airflow/.local/lib/python3.7/site-packages/sqlalchemy/pool/base.py", line 256, in _create_connection
    return _ConnectionRecord(self)
  File "/home/airflow/.local/lib/python3.7/site-packages/sqlalchemy/pool/base.py", line 371, in __init__
    self.__connect()
  File "/home/airflow/.local/lib/python3.7/site-packages/sqlalchemy/pool/base.py", line 666, in __connect
    pool.logger.debug("Error on connect(): %s", e)
  File "/home/airflow/.local/lib/python3.7/site-packages/sqlalchemy/util/langhelpers.py", line 72, in __exit__
    with_traceback=exc_tb,
  File "/home/airflow/.local/lib/python3.7/site-packages/sqlalchemy/util/compat.py", line 207, in raise_
    raise exception
  File "/home/airflow/.local/lib/python3.7/site-packages/sqlalchemy/pool/base.py", line 661, in __connect
    self.dbapi_connection = connection = pool._invoke_creator(self)
  File "/home/airflow/.local/lib/python3.7/site-packages/sqlalchemy/engine/create.py", line 590, in connect
    return dialect.connect(*cargs, **cparams)
  File "/home/airflow/.local/lib/python3.7/site-packages/sqlalchemy/engine/default.py", line 584, in connect
    return self.dbapi.connect(*cargs, **cparams)
  File "/home/airflow/.local/lib/python3.7/site-packages/psycopg2/__init__.py", line 122, in connect
    conn = _connect(dsn, connection_factory=connection_factory, **kwasync)
sqlalchemy.exc.OperationalError: (psycopg2.OperationalError) connection to server at "pgdatabase" (172.20.0.2), port 5432 failed: FATAL:  password authentication failed for user "***"

(Background on this error at: https://sqlalche.me/e/14/e3q8)
[2022-07-12 14:48:58,807] {taskinstance.py:1420} INFO - Marking task as UP_FOR_RETRY. dag_id=data_ingestion_local, task_id=ingest_data, execution_date=20220712T144837, start_date=20220712T144854, end_date=20220712T144858
[2022-07-12 14:48:58,840] {standard_task_runner.py:97} ERROR - Failed to execute job 7 for task ingest_data ((psycopg2.OperationalError) connection to server at "pgdatabase" (172.20.0.2), port 5432 failed: FATAL:  password authentication failed for user "***"

(Background on this error at: https://sqlalche.me/e/14/e3q8); 262)
[2022-07-12 14:48:59,063] {local_task_job.py:156} INFO - Task exited with return code 1
[2022-07-12 14:48:59,152] {local_task_job.py:273} INFO - 0 downstream tasks scheduled from follow-on schedule check
